<mujoco>
          <site name="edl_l-P1" pos="-0.016 -0.1157 -0.0205"></site>
          <site name="edl_l-P2" pos="0.0164 -0.376 -0.0112"></site>
          <site name="ehl_l-P1" pos="-0.014 -0.155 -0.0189"></site>
          <site name="ehl_l-P2" pos="0.0071 -0.2909 -0.0164"></site>
          <site name="ehl_l-P3" pos="0.02 -0.3693 0.0028"></site>
          <site name="fdl_l-P1" pos="-0.0023 -0.1832 0.0018"></site>
          <site name="fdl_l-P2" pos="-0.0176 -0.3645 0.0124"></site>
          <site name="fhl_l-P1" pos="-0.031 -0.2163 -0.02"></site>
          <site name="fhl_l-P2" pos="-0.0242 -0.3671 0.0076"></site>
          <body name="talus_l" pos="   -0.01     -0.4        0" quat="1.0 6.036754011562992e-18 -1.5193252867388614e-18 -2.498419531737724e-19">
            <geom name="l_talus" type="mesh" mesh="l_talus" class="collision"></geom>
            <inertial pos="       0        0        0" mass="0.1" fullinertia="   0.001    0.001    0.001        0        0        0"></inertial>
            <joint name="ankle_angle_l" type="hinge" pos="0 0 0" axis="0.105014 0.174022 0.979126" limited="true" range="-0.698132 0.523599" ref="0"></joint>
            <body name="calcn_l" pos="-0.04877 -0.04195 -0.00792" quat="1.0 5.320429553087796e-19 -1.609289071159989e-17 -2.1848634538867752e-17">
              <site name="foot_spring_left_human" group="1" size="0.01" pos="0 0 1"></site>
              <geom name="l_foot" type="mesh" mesh="l_foot" class="collision"></geom>
              <inertial pos="     0.1     0.03        0" mass="1.25" fullinertia="  0.0014   0.0039   0.0041        0        0        0"></inertial>
              <site name="edl_l-P3" pos="0.0919 0.036 -0.0008"></site>
              <site name="edl_l-P4" pos="0.1616 0.0055 -0.013"></site>
              <site name="ehl_l-P4" pos="0.097 0.0389 0.0211"></site>
              <site name="ehl_l-P5" pos="0.1293 0.0309 0.0257"></site>
              <site name="ehl_l-P6" pos="0.1734 0.0139 0.028"></site>
              <site name="fdl_l-P3" pos="0.0436 0.0315 0.028"></site>
              <site name="fdl_l-P4" pos="0.0708 0.0176 0.0263"></site>
              <site name="fdl_l-P5" pos="0.1658 -0.0081 -0.0116"></site>
              <site name="fhl_l-P3" pos="0.0374 0.0276 0.0241"></site>
              <site name="fhl_l-P4" pos="0.1038 0.0068 0.0256"></site>
              <site name="fhl_l-P5" pos="0.1726 -0.0053 0.0269"></site>
              <site name="gaslat140_l-P2" pos="0.0044 0.031 0.0053"></site>
              <site name="gasmed_l-P2" pos="0.0044 0.031 0.0053"></site>
              <site name="perbrev_l-P4" pos="0.0471 0.027 -0.0233"></site>
              <site name="perbrev_l-P5" pos="0.0677 0.0219 -0.0343"></site>
              <site name="perlong_l-P4" pos="0.0438 0.023 -0.0221"></site>
              <site name="perlong_l-P5" pos="0.0681 0.0106 -0.0284"></site>
              <site name="perlong_l-P6" pos="0.0852 0.0069 -0.0118"></site>
              <site name="perlong_l-P7" pos="0.1203 0.0085 0.0184"></site>
              <site name="soleus_l-P2" pos="0.0044 0.031 0.0053"></site>
              <site name="tibant_l-P4" pos="0.1166 0.0178 0.0305"></site>
              <site name="tibpost_l-P3" pos="0.0417 0.0334 0.0286"></site>
              <site name="tibpost_l-P4" pos="0.0772 0.0159 0.0281"></site>
              <joint name="subtalar_angle_l" type="hinge" pos="0 0 0" axis="-0.78718 -0.604747 -0.120949" limited="true" range="-0.349066 0.349066" ref="0"></joint>
              <body name="toes_l" pos="  0.1788   -0.002 -0.00108" quat="1.0 1.314867274624753e-31 2.6810890689525335e-17 3.939849802505862e-32">
                <geom name="l_bofoot" type="mesh" mesh="l_bofoot" class="collision"></geom>
                <inertial pos="  0.0346    0.006   0.0175" mass="0.2166" fullinertia="  0.0001   0.0002    0.001        0        0        0"></inertial>
                <site name="toes_site_l" pos="0.06 0 0" size="0.01"></site>
                <site name="calcn_site_l" pos="-0.18 0 0" size="0.01"></site>
                <site name="edl_l-P5" pos="0.0003 0.0047 -0.0153"></site>
                <site name="edl_l-P6" pos="0.0443 -0.0004 -0.025"></site>
                <site name="ehl_l-P7" pos="0.0298 0.0041 0.0245"></site>
                <site name="ehl_l-P8" pos="0.0563 0.0034 0.0186"></site>
                <site name="fdl_l-P6" pos="-0.0019 -0.0078 -0.0147"></site>
                <site name="fdl_l-P7" pos="0.0285 -0.0071 -0.0215"></site>
                <site name="fdl_l-P8" pos="0.0441 -0.006 -0.0242"></site>
                <site name="fhl_l-P6" pos="0.0155 -0.0064 0.0265"></site>
                <site name="fhl_l-P7" pos="0.0562 -0.0102 0.0181"></site>
                <joint name="mtp_angle_l" type="hinge" pos="0 0 0" axis="-0.580954 2.6299e-15 -0.813936" limited="true" range="-0.523599 0.523599" ref="0"></joint>
              </body>
            </body>
          </body>
</mujoco>