<mujoco>
      <geom name="r_pelvis" type="mesh" mesh="r_pelvis" class="collision"></geom>
      <geom name="l_pelvis" type="mesh" mesh="l_pelvis" class="collision"></geom>
      <inertial pos=" -0.0707        0        0" mass="11.777" fullinertia="  0.1028   0.0871   0.0579        0        0        0"></inertial>
      <site name="addbrev_r-P1" pos="-0.0191 -0.094 0.0154"></site>
      <site name="addlong_r-P1" pos="-0.00758 -0.0889 0.01888"></site>
      <site name="addmagDist_r-P1" pos="-0.07404 -0.12767 0.03982"></site>
      <site name="addmagIsch_r-P1" pos="-0.08962 -0.12976 0.04171"></site>
      <site name="addmagMid_r-P1" pos="-0.05266 -0.12075 0.02854"></site>
      <site name="addmagProx_r-P1" pos="-0.03098 -0.10755 0.01365"></site>
      <site name="bflh_r-P1" pos="-0.104 -0.1191 0.0586"></site>
      <site name="glmax1_r-P1" pos="-0.1231 0.0345 0.0563"></site>
      <site name="glmax1_r-P2" pos="-0.1257 -0.0242 0.0779"></site>
      <site name="glmax2_r-P1" pos="-0.1317 0.0087 0.0462"></site>
      <site name="glmax2_r-P2" pos="-0.1344 -0.0609 0.0813"></site>
      <site name="glmax3_r-P1" pos="-0.13 -0.0525 0.009"></site>
      <site name="glmax3_r-P2" pos="-0.1273 -0.1263 0.0435"></site>
      <site name="glmed1_r-P1" pos="-0.0445 0.0245 0.1172"></site>
      <site name="glmed2_r-P1" pos="-0.085 0.0316 0.0675"></site>
      <site name="glmed3_r-P1" pos="-0.1152 -0.0073 0.0526"></site>
      <site name="glmin1_r-P1" pos="-0.0464 -0.0149 0.1042"></site>
      <site name="glmin2_r-P1" pos="-0.0616 -0.0142 0.0971"></site>
      <site name="glmin3_r-P1" pos="-0.0789 -0.0155 0.0798"></site>
      <site name="grac_r-P1" pos="-0.04736 -0.12932 0.02456"></site>
      <site name="iliacus_r-P1" pos="-0.0605 0.0309 0.0843"></site>
      <site name="iliacus_r-P2" pos="-0.0135 -0.0557 0.0756"></site>
      <site name="piri_r-P1" pos="-0.10181 -0.00653 0.01351"></site>
      <site name="piri_r-P2" pos="-0.10202 -0.03066 0.06092"></site>
      <site name="psoas_r-P1" pos="-0.0606 0.062 0.039"></site>
      <site name="psoas_r-P2" pos="-0.0205 -0.0654 0.0656"></site>
      <site name="recfem_r-P1" pos="-0.024 -0.0388 0.0933"></site>
      <site name="sart_r-P1" pos="-0.0195 -0.0156 0.1056"></site>
      <site name="semimem_r-P1" pos="-0.0987 -0.114 0.0614"></site>
      <site name="semiten_r-P1" pos="-0.1038 -0.1253 0.0515"></site>
      <site name="tfl_r-P1" pos="-0.0311 0.0214 0.1241"></site>
      <site name="addbrev_l-P1" pos="-0.0191 -0.094 -0.0154"></site>
      <site name="addlong_l-P1" pos="-0.00758 -0.0889 -0.01888"></site>
      <site name="addmagDist_l-P1" pos="-0.07404 -0.12767 -0.03982"></site>
      <site name="addmagIsch_l-P1" pos="-0.08962 -0.12976 -0.04171"></site>
      <site name="addmagMid_l-P1" pos="-0.05266 -0.12075 -0.02854"></site>
      <site name="addmagProx_l-P1" pos="-0.03098 -0.10755 -0.01365"></site>
      <site name="bflh_l-P1" pos="-0.104 -0.1191 -0.0586"></site>
      <site name="glmax1_l-P1" pos="-0.1231 0.0345 -0.0563"></site>
      <site name="glmax1_l-P2" pos="-0.1257 -0.0242 -0.0779"></site>
      <site name="glmax2_l-P1" pos="-0.1317 0.0087 -0.0462"></site>
      <site name="glmax2_l-P2" pos="-0.1344 -0.0609 -0.0813"></site>
      <site name="glmax3_l-P1" pos="-0.13 -0.0525 -0.009"></site>
      <site name="glmax3_l-P2" pos="-0.1273 -0.1263 -0.0435"></site>
      <site name="glmed1_l-P1" pos="-0.0445 0.0245 -0.1172"></site>
      <site name="glmed2_l-P1" pos="-0.085 0.0316 -0.0675"></site>
      <site name="glmed3_l-P1" pos="-0.1152 -0.0073 -0.0526"></site>
      <site name="glmin1_l-P1" pos="-0.0464 -0.0149 -0.1042"></site>
      <site name="glmin2_l-P1" pos="-0.0616 -0.0142 -0.0971"></site>
      <site name="glmin3_l-P1" pos="-0.0789 -0.0155 -0.0798"></site>
      <site name="grac_l-P1" pos="-0.04736 -0.12932 -0.02456"></site>
      <site name="iliacus_l-P1" pos="-0.0605 0.0309 -0.0843"></site>
      <site name="iliacus_l-P2" pos="-0.0135 -0.0557 -0.0756"></site>
      <site name="piri_l-P1" pos="-0.10181 -0.00653 -0.01351"></site>
      <site name="piri_l-P2" pos="-0.10202 -0.03066 -0.06092"></site>
      <site name="psoas_l-P1" pos="-0.0606 0.062 -0.039"></site>
      <site name="psoas_l-P2" pos="-0.0205 -0.0654 -0.0656"></site>
      <site name="recfem_l-P1" pos="-0.024 -0.0388 -0.0933"></site>
      <site name="sart_l-P1" pos="-0.0195 -0.0156 -0.1056"></site>
      <site name="semimem_l-P1" pos="-0.0987 -0.114 -0.0614"></site>
      <site name="semiten_l-P1" pos="-0.1038 -0.1253 -0.0515"></site>
      <site name="tfl_l-P1" pos="-0.0311 0.0214 -0.1241"></site>
      <body name="femur_r" pos="-0.056276 -0.07849  0.07726" quat="1.0 0.0 0.0 0.0">
        <geom name="r_femur" type="mesh" mesh="r_femur" class="collision"></geom>
        <inertial pos="       0    -0.17        0" mass="9.3014" fullinertia="  0.1339   0.0351   0.1412        0        0        0"></inertial>
        <site name="addbrev_r-P2" pos="-0.002 -0.118 0.0249"></site>
        <site name="addlong_r-P2" pos="0.01126 -0.23937 0.01583"></site>
        <site name="addmagDist_r-P2" pos="0.01125 -0.2625 0.0193"></site>
        <site name="addmagIsch_r-P2" pos="0.00481 -0.38797 -0.03273"></site>
        <site name="addmagMid_r-P2" pos="0.00242 -0.1624 0.02922"></site>
        <site name="addmagProx_r-P2" pos="-0.01527 -0.07886 0.03202"></site>
        <site name="bfsh_r-P1" pos="0.005 -0.2111 0.0234"></site>
        <site name="gaslat_r-P1" pos="-0.003 -0.3814 0.0277"></site>
        <site name="gasmed_r-P1" pos="0.008 -0.3788 -0.0208"></site>
        <site name="glmax1_r-P3" pos="-0.0444 -0.0326 0.0302"></site>
        <site name="glmax1_r-P4" pos="-0.0277 -0.0566 0.047"></site>
        <site name="glmax2_r-P3" pos="-0.045 -0.0584 0.0252"></site>
        <site name="glmax2_r-P4" pos="-0.0156 -0.1016 0.0419"></site>
        <site name="glmax3_r-P3" pos="-0.0281 -0.1125 0.0094"></site>
        <site name="glmax3_r-P4" pos="-0.006 -0.1419 0.0411"></site>
        <site name="glmed1_r-P2" pos="-0.0218 -0.0117 0.0555"></site>
        <site name="glmed2_r-P2" pos="-0.0258 -0.0058 0.0527"></site>
        <site name="glmed3_r-P2" pos="-0.0309 -0.0047 0.0518"></site>
        <site name="glmin1_r-P2" pos="-0.0072 -0.0104 0.056"></site>
        <site name="glmin2_r-P2" pos="-0.0096 -0.0104 0.056"></site>
        <site name="glmin3_r-P2" pos="-0.0135 -0.0083 0.055"></site>
        <site name="iliacus_r-P3" pos="-0.0023 -0.0565 0.0139"></site>
        <site name="iliacus_r-P4" pos="-0.0122 -0.0637 0.0196"></site>
        <site name="piri_r-P3" pos="-0.0148 -0.0036 0.0437"></site>
        <site name="psoas_r-P3" pos="-0.0132 -0.0467 0.0046"></site>
        <site name="psoas_r-P4" pos="-0.0235 -0.0524 0.0088"></site>
        <site name="sart_r-P2" pos="-0.003 -0.3568 -0.0421"></site>
        <site name="tfl_r-P2" pos="0.0294 -0.0995 0.0597"></site>
        <site name="tfl_r-P3" pos="0.0107 -0.405 0.0324"></site>
        <site name="vasint_r-P1" pos="0.029 -0.1924 0.031"></site>
        <site name="vasint_r-P2" pos="0.0335 -0.2084 0.0285"></site>
        <site name="vaslat_r-P1" pos="0.0048 -0.1854 0.0349"></site>
        <site name="vaslat_r-P2" pos="0.0269 -0.2591 0.0409"></site>
        <site name="vasmed_r-P1" pos="0.014 -0.2099 0.0188"></site>
        <site name="vasmed_r-P2" pos="0.0356 -0.2769 0.0009"></site>
        <joint name="hip_flexion_r" type="hinge" pos="0 0 0" axis="       0        0        1" limited="true" range="-0.523599   2.0944" ref="0"></joint>
        <joint name="hip_adduction_r" type="hinge" pos="0 0 0" axis="       1        0        0" limited="true" range="-0.872665 0.523599" ref="0"></joint>
        <joint name="hip_rotation_r" type="hinge" pos="0 0 0" axis="       0        1        0" limited="true" range="-0.698132 0.698132" ref="0"></joint>
        <body name="tibia_r" pos="-4.6e-07 -0.404425 -0.00126526" quat="1.0 7.240636975890137e-18 -9.456205735995121e-17 -2.960068750797159e-20">
          <geom name="r_tibia" type="mesh" mesh="r_tibia" class="collision"></geom>
          <geom name="r_fibula" type="mesh" mesh="r_fibula" class="collision"></geom>
          <inertial pos="       0  -0.1867        0" mass="3.7075" fullinertia="  0.0504   0.0051   0.0511        0        0        0"></inertial>
          <site name="bflh_r-P2" pos="-0.0337 -0.035 0.0253"></site>
          <site name="bflh_r-P3" pos="-0.0287 -0.0455 0.0303"></site>
          <site name="bfsh_r-P2" pos="-0.0301 -0.0419 0.0318"></site>
          <site name="edl_r-P1" pos="-0.016 -0.1157 0.0205"></site>
          <site name="edl_r-P2" pos="0.0164 -0.376 0.0112"></site>
          <site name="ehl_r-P1" pos="-0.014 -0.155 0.0189"></site>
          <site name="ehl_r-P2" pos="0.0071 -0.2909 0.0164"></site>
          <site name="ehl_r-P3" pos="0.02 -0.3693 -0.0028"></site>
          <site name="fdl_r-P1" pos="-0.0023 -0.1832 -0.0018"></site>
          <site name="fdl_r-P2" pos="-0.0176 -0.3645 -0.0124"></site>
          <site name="fhl_r-P1" pos="-0.031 -0.2163 0.02"></site>
          <site name="fhl_r-P2" pos="-0.0242 -0.3671 -0.0076"></site>
          <site name="grac_r-P2" pos="-0.01842 -0.04755 -0.02961"></site>
          <site name="grac_r-P3" pos="0.00178 -0.06962 -0.01573"></site>
          <site name="perbrev_r-P1" pos="-0.0243 -0.2532 0.0251"></site>
          <site name="perbrev_r-P2" pos="-0.0339 -0.3893 0.0249"></site>
          <site name="perbrev_r-P3" pos="-0.0285 -0.4004 0.0255"></site>
          <site name="perlong_r-P1" pos="-0.02 -0.1373 0.0282"></site>
          <site name="perlong_r-P2" pos="-0.0317 -0.39 0.0237"></site>
          <site name="perlong_r-P3" pos="-0.0272 -0.4014 0.024"></site>
          <site name="recfem_r-P5" pos="0.0326 -0.06312 -0.00047"></site>
          <site name="sart_r-P3" pos="-0.0251 -0.0401 -0.0365"></site>
          <site name="sart_r-P4" pos="-0.0159 -0.0599 -0.0264"></site>
          <site name="sart_r-P5" pos="0.0136 -0.081 -0.0026"></site>
          <site name="semimem_r-P2" pos="-0.029 -0.0417 -0.0196"></site>
          <site name="semiten_r-P2" pos="-0.0312 -0.0508 -0.0229"></site>
          <site name="semiten_r-P3" pos="0.0019 -0.0773 -0.0117"></site>
          <site name="soleus_r-P1" pos="-0.0076 -0.0916 0.0098"></site>
          <site name="tfl_r-P4" pos="0.0108 -0.041 0.0346"></site>
          <site name="tibant_r-P1" pos="0.0154 -0.1312 0.0162"></site>
          <site name="tibant_r-P2" pos="0.0251 -0.1906 0.0128"></site>
          <site name="tibant_r-P3" pos="0.0233 -0.3659 -0.0132"></site>
          <site name="tibpost_r-P1" pos="-0.0041 -0.1304 0.0103"></site>
          <site name="tibpost_r-P2" pos="-0.0164 -0.3655 -0.0175"></site>
          <site name="vasint_r-P5" pos="0.03257 -0.0632 0.00043"></site>
          <site name="vaslat_r-P5" pos="0.03254 -0.06338 0.00511"></site>
          <site name="vasmed_r-P5" pos="0.0319 -0.06357 -0.00678"></site>
          <joint name="knee_angle_r_translation2" type="slide" pos="0 0 0" axis="0.992246 0.123982 -0.00878916" limited="true" range="7.69254e-11 0.006792" ref="0"></joint>
          <joint name="knee_angle_r_translation1" type="slide" pos="0 0 0" axis="-0.124293 0.989762 -0.0701648" limited="true" range="9.53733e-08 0.00159883" ref="0"></joint>
          <joint name="knee_angle_r" type="hinge" pos="0 0 0" axis="-3.98373e-10 -0.0707131 -0.997497" limited="true" range="       0   2.0944" ref="0"></joint>
          <joint name="knee_angle_r_rotation2" type="hinge" pos="0 0 0" axis="0.992246 0.123982 -0.00878916" limited="true" range="-0.00167821 0.0335354" ref="0"></joint>
          <joint name="knee_angle_r_rotation3" type="hinge" pos="0 0 0" axis="-0.124293 0.989762 -0.0701648" limited="true" range="1.08939e-08 0.262788" ref="0"></joint>
          <body name="talus_r" pos="   -0.01     -0.4        0" quat="1.0 -6.036754011562992e-18 1.5193252867388614e-18 -2.498419531737724e-19">
            <geom name="r_talus" type="mesh" mesh="r_talus" class="collision"></geom>
            <inertial pos="       0        0        0" mass="0.1" fullinertia="   0.001    0.001    0.001        0        0        0"></inertial>
            <joint name="ankle_angle_r" type="hinge" pos="0 0 0" axis="-0.105014 -0.174022 0.979126" limited="true" range="-0.698132 0.523599" ref="0"></joint>
            <body name="calcn_r" pos="-0.04877 -0.04195  0.00792" quat="1.0 -5.320429553087796e-19 1.609289071159989e-17 -2.1848634538867752e-17">
              <geom name="r_foot" type="mesh" mesh="r_foot" class="collision"></geom>
              <inertial pos="     0.1     0.03        0" mass="1.25" fullinertia="  0.0014   0.0039   0.0041        0        0        0"></inertial>
              <site name="edl_r-P3" pos="0.0919 0.036 0.0008"></site>
              <site name="edl_r-P4" pos="0.1616 0.0055 0.013"></site>
              <site name="ehl_r-P4" pos="0.097 0.0389 -0.0211"></site>
              <site name="ehl_r-P5" pos="0.1293 0.0309 -0.0257"></site>
              <site name="ehl_r-P6" pos="0.1734 0.0139 -0.028"></site>
              <site name="fdl_r-P3" pos="0.0436 0.0315 -0.028"></site>
              <site name="fdl_r-P4" pos="0.0708 0.0176 -0.0263"></site>
              <site name="fdl_r-P5" pos="0.1658 -0.0081 0.0116"></site>
              <site name="fhl_r-P3" pos="0.0374 0.0276 -0.0241"></site>
              <site name="fhl_r-P4" pos="0.1038 0.0068 -0.0256"></site>
              <site name="fhl_r-P5" pos="0.1726 -0.0053 -0.0269"></site>
              <site name="gaslat_r-P2" pos="0.0044 0.031 -0.0053"></site>
              <site name="gasmed_r-P2" pos="0.0044 0.031 -0.0053"></site>
              <site name="perbrev_r-P4" pos="0.0471 0.027 0.0233"></site>
              <site name="perbrev_r-P5" pos="0.0677 0.0219 0.0343"></site>
              <site name="perlong_r-P4" pos="0.0438 0.023 0.0221"></site>
              <site name="perlong_r-P5" pos="0.0681 0.0106 0.0284"></site>
              <site name="perlong_r-P6" pos="0.0852 0.0069 0.0118"></site>
              <site name="perlong_r-P7" pos="0.1203 0.0085 -0.0184"></site>
              <site name="soleus_r-P2" pos="0.0044 0.031 -0.0053"></site>
              <site name="tibant_r-P4" pos="0.1166 0.0178 -0.0305"></site>
              <site name="tibpost_r-P3" pos="0.0417 0.0334 -0.0286"></site>
              <site name="tibpost_r-P4" pos="0.0772 0.0159 -0.0281"></site>
              <joint name="subtalar_angle_r" type="hinge" pos="0 0 0" axis=" 0.78718 0.604747 -0.120949" limited="true" range="-0.349066 0.349066" ref="0"></joint>
              <body name="toes_r" pos="  0.1788   -0.002  0.00108" quat="1.0 1.314867274624753e-31 -2.6810890689525335e-17 -3.939849802505862e-32">
                <geom name="r_bofoot" type="mesh" mesh="r_bofoot" class="collision"></geom>
                <inertial pos="  0.0346    0.006  -0.0175" mass="0.2166" fullinertia="  0.0001   0.0002    0.001        0        0        0"></inertial>
                <site name="edl_r-P5" pos="0.0003 0.0047 0.0153"></site>
                <site name="edl_r-P6" pos="0.0443 -0.0004 0.025"></site>
                <site name="ehl_r-P7" pos="0.0298 0.0041 -0.0245"></site>
                <site name="ehl_r-P8" pos="0.0563 0.0034 -0.0186"></site>
                <site name="fdl_r-P6" pos="-0.0019 -0.0078 0.0147"></site>
                <site name="fdl_r-P7" pos="0.0285 -0.0071 0.0215"></site>
                <site name="fdl_r-P8" pos="0.0441 -0.006 0.0242"></site>
                <site name="fhl_r-P6" pos="0.0155 -0.0064 -0.0265"></site>
                <site name="fhl_r-P7" pos="0.0562 -0.0102 -0.0181"></site>
                <joint name="mtp_angle_r" type="hinge" pos="0 0 0" axis="0.580954 2.6299e-15 -0.813936" limited="true" range="-0.523599 0.523599" ref="0"></joint>
              </body>
            </body>
          </body>
        </body>
        <body name="patella_r" pos="-0.00809 -0.40796        0" quat="1.0 0.0 0.0 0.0">
          <geom name="r_patella" type="mesh" mesh="r_patella" class="collision"></geom>
          <inertial pos="  0.0018   0.0264        0" mass="0.0862" fullinertia="2.87e-06 1.311e-05 1.311e-05        0        0        0"></inertial>
          <site name="recfem_r-P2" pos="0.01 0.049 0.0007"></site>
          <site name="recfem_r-P3" pos="0.0121 0.0437 -0.001"></site>
          <site name="recfem_r-P4" pos="0.005 0.00247 3e-005"></site>
          <site name="vasint_r-P3" pos="0.0058 0.048 -0.0006"></site>
          <site name="vasint_r-P4" pos="0.005 0.00247 -0.00039"></site>
          <site name="vaslat_r-P3" pos="0.0103 0.0423 0.0141"></site>
          <site name="vaslat_r-P4" pos="0.005 0.00247 0.00733"></site>
          <site name="vasmed_r-P3" pos="0.0063 0.0445 -0.017"></site>
          <site name="vasmed_r-P4" pos="0.005 0.00247 -0.0085"></site>
          <joint name="knee_angle_r_beta_translation2" type="slide" pos="0 0 0" axis="       0        1        0" limited="true" range="-0.0408267 -0.0108281" ref="0"></joint>
          <joint name="knee_angle_r_beta_translation1" type="slide" pos="0 0 0" axis="       1        0        0" limited="true" range="-0.0227731 0.0524192" ref="0"></joint>
          <joint name="knee_angle_r_beta_rotation1" type="hinge" pos="0 0 0" axis="       0        0        1" limited="true" range="-1.79241 0.010506" ref="0"></joint>
        </body>
      </body>
      <body name="femur_l" pos="-0.056276 -0.07849 -0.07726" quat="1.0 0.0 0.0 0.0">
        <geom name="l_femur" type="mesh" mesh="l_femur" class="collision"></geom>
        <inertial pos="       0    -0.17        0" mass="9.3014" fullinertia="  0.1339   0.0351   0.1412        0        0        0"></inertial>
        <site name="addbrev_l-P2" pos="-0.002 -0.118 -0.0249"></site>
        <site name="addlong_l-P2" pos="0.01126 -0.23937 -0.01583"></site>
        <site name="addmagDist_l-P2" pos="0.01125 -0.2625 -0.0193"></site>
        <site name="addmagIsch_l-P2" pos="0.00481 -0.38797 0.03273"></site>
        <site name="addmagMid_l-P2" pos="0.00242 -0.1624 -0.02922"></site>
        <site name="addmagProx_l-P2" pos="-0.01527 -0.07886 -0.03202"></site>
        <site name="bfsh_l-P1" pos="0.005 -0.2111 -0.0234"></site>
        <site name="gaslat_l-P1" pos="-0.003 -0.3814 -0.0277"></site>
        <site name="gasmed_l-P1" pos="0.008 -0.3788 0.0208"></site>
        <site name="glmax1_l-P3" pos="-0.0444 -0.0326 -0.0302"></site>
        <site name="glmax1_l-P4" pos="-0.0277 -0.0566 -0.047"></site>
        <site name="glmax2_l-P3" pos="-0.045 -0.0584 -0.0252"></site>
        <site name="glmax2_l-P4" pos="-0.0156 -0.1016 -0.0419"></site>
        <site name="glmax3_l-P3" pos="-0.0281 -0.1125 -0.0094"></site>
        <site name="glmax3_l-P4" pos="-0.006 -0.1419 -0.0411"></site>
        <site name="glmed1_l-P2" pos="-0.0218 -0.0117 -0.0555"></site>
        <site name="glmed2_l-P2" pos="-0.0258 -0.0058 -0.0527"></site>
        <site name="glmed3_l-P2" pos="-0.0309 -0.0047 -0.0518"></site>
        <site name="glmin1_l-P2" pos="-0.0072 -0.0104 -0.056"></site>
        <site name="glmin2_l-P2" pos="-0.0096 -0.0104 -0.056"></site>
        <site name="glmin3_l-P2" pos="-0.0135 -0.0083 -0.055"></site>
        <site name="iliacus_l-P3" pos="-0.0023 -0.0565 -0.0139"></site>
        <site name="iliacus_l-P4" pos="-0.0122 -0.0637 -0.0196"></site>
        <site name="piri_l-P3" pos="-0.0148 -0.0036 -0.0437"></site>
        <site name="psoas_l-P3" pos="-0.0132 -0.0467 -0.0046"></site>
        <site name="psoas_l-P4" pos="-0.0235 -0.0524 -0.0088"></site>
        <site name="sart_l-P2" pos="-0.003 -0.3568 0.0421"></site>
        <site name="tfl_l-P2" pos="0.0294 -0.0995 -0.0597"></site>
        <site name="tfl_l-P3" pos="0.0107 -0.405 -0.0324"></site>
        <site name="vasint_l-P1" pos="0.029 -0.1924 -0.031"></site>
        <site name="vasint_l-P2" pos="0.0335 -0.2084 -0.0285"></site>
        <site name="vaslat_l-P1" pos="0.0048 -0.1854 -0.0349"></site>
        <site name="vaslat_l-P2" pos="0.0269 -0.2591 -0.0409"></site>
        <site name="vasmed_l-P1" pos="0.014 -0.2099 -0.0188"></site>
        <site name="vasmed_l-P2" pos="0.0356 -0.2769 -0.0009"></site>
        <joint name="hip_flexion_l" type="hinge" pos="0 0 0" axis="       0        0        1" limited="true" range="-0.523599   2.0944" ref="0"></joint>
        <joint name="hip_adduction_l" type="hinge" pos="0 0 0" axis="       -1        0        0" limited="true" range="-0.872665 0.523599" ref="0"></joint>
        <joint name="hip_rotation_l" type="hinge" pos="0 0 0" axis="       0        -1        0" limited="true" range="-0.698132 0.698132" ref="0"></joint>
        <body name="tibia_l" pos="-4.6e-07 -0.404425 0.00126526" quat="1.0 -7.240636975890137e-18 9.456205735995121e-17 -2.960068750797159e-20">
          <geom name="l_tibia" type="mesh" mesh="l_tibia" class="collision"></geom>
          <geom name="l_fibula" type="mesh" mesh="l_fibula" class="collision"></geom>
          <inertial pos="       0  -0.1867        0" mass="3.7075" fullinertia="  0.0504   0.0051   0.0511        0        0        0"></inertial>
          <site name="bflh_l-P2" pos="-0.0337 -0.035 -0.0253"></site>
          <site name="bflh_l-P3" pos="-0.0287 -0.0455 -0.0303"></site>
          <site name="bfsh_l-P2" pos="-0.0301 -0.0419 -0.0318"></site>
          <site name="edl_l-P1" pos="-0.016 -0.1157 -0.0205"></site>
          <site name="edl_l-P2" pos="0.0164 -0.376 -0.0112"></site>
          <site name="ehl_l-P1" pos="-0.014 -0.155 -0.0189"></site>
          <site name="ehl_l-P2" pos="0.0071 -0.2909 -0.0164"></site>
          <site name="ehl_l-P3" pos="0.02 -0.3693 0.0028"></site>
          <site name="fdl_l-P1" pos="-0.0023 -0.1832 0.0018"></site>
          <site name="fdl_l-P2" pos="-0.0176 -0.3645 0.0124"></site>
          <site name="fhl_l-P1" pos="-0.031 -0.2163 -0.02"></site>
          <site name="fhl_l-P2" pos="-0.0242 -0.3671 0.0076"></site>
          <site name="grac_l-P2" pos="-0.01842 -0.04755 0.02961"></site>
          <site name="grac_l-P3" pos="0.00178 -0.06962 0.01573"></site>
          <site name="perbrev_l-P1" pos="-0.0243 -0.2532 -0.0251"></site>
          <site name="perbrev_l-P2" pos="-0.0339 -0.3893 -0.0249"></site>
          <site name="perbrev_l-P3" pos="-0.0285 -0.4004 -0.0255"></site>
          <site name="perlong_l-P1" pos="-0.02 -0.1373 -0.0282"></site>
          <site name="perlong_l-P2" pos="-0.0317 -0.39 -0.0237"></site>
          <site name="perlong_l-P3" pos="-0.0272 -0.4014 -0.024"></site>
          <site name="recfem_l-P5" pos="0.0326 -0.06312 0.00047"></site>
          <site name="sart_l-P3" pos="-0.0251 -0.0401 0.0365"></site>
          <site name="sart_l-P4" pos="-0.0159 -0.0599 0.0264"></site>
          <site name="sart_l-P5" pos="0.0136 -0.081 0.0026"></site>
          <site name="semimem_l-P2" pos="-0.029 -0.0417 0.0196"></site>
          <site name="semiten_l-P2" pos="-0.0312 -0.0508 0.0229"></site>
          <site name="semiten_l-P3" pos="0.0019 -0.0773 0.0117"></site>
          <site name="soleus_l-P1" pos="-0.0076 -0.0916 -0.0098"></site>
          <site name="tfl_l-P4" pos="0.0108 -0.041 -0.0346"></site>
          <site name="tibant_l-P1" pos="0.0154 -0.1312 -0.0162"></site>
          <site name="tibant_l-P2" pos="0.0251 -0.1906 -0.0128"></site>
          <site name="tibant_l-P3" pos="0.0233 -0.3659 0.0132"></site>
          <site name="tibpost_l-P1" pos="-0.0041 -0.1304 -0.0103"></site>
          <site name="tibpost_l-P2" pos="-0.0164 -0.3655 0.0175"></site>
          <site name="vasint_l-P5" pos="0.03257 -0.0632 -0.00043"></site>
          <site name="vaslat_l-P5" pos="0.03254 -0.06338 -0.00511"></site>
          <site name="vasmed_l-P5" pos="0.0319 -0.06357 0.00678"></site>
          <joint name="knee_angle_l_translation2" type="slide" pos="0 0 0" axis="-0.992246 -0.123982 -0.00878916" limited="true" range="-0.006792 -7.69254e-11" ref="0"></joint>
          <joint name="knee_angle_l_translation1" type="slide" pos="0 0 0" axis="-0.124293 0.989762 0.0701648" limited="true" range="9.53733e-08 0.00159883" ref="0"></joint>
          <joint name="knee_angle_l" type="hinge" pos="0 0 0" axis="3.98373e-10 0.0707131 -0.997497" limited="true" range="       0   2.0944" ref="0"></joint>
          <joint name="knee_angle_l_rotation2" type="hinge" pos="0 0 0" axis="-0.992246 -0.123982 -0.00878916" limited="true" range="-0.00167821 0.0335354" ref="0"></joint>
          <joint name="knee_angle_l_rotation3" type="hinge" pos="0 0 0" axis="-0.124293 0.989762 0.0701648" limited="true" range="-0.262788 -1.08939e-08" ref="0"></joint>
          <body name="talus_l" pos="   -0.01     -0.4        0" quat="1.0 6.036754011562992e-18 -1.5193252867388614e-18 -2.498419531737724e-19">
            <geom name="l_talus" type="mesh" mesh="l_talus" class="collision"></geom>
            <inertial pos="       0        0        0" mass="0.1" fullinertia="   0.001    0.001    0.001        0        0        0"></inertial>
            <joint name="ankle_angle_l" type="hinge" pos="0 0 0" axis="0.105014 0.174022 0.979126" limited="true" range="-0.698132 0.523599" ref="0"></joint>
            <body name="calcn_l" pos="-0.04877 -0.04195 -0.00792" quat="1.0 5.320429553087796e-19 -1.609289071159989e-17 -2.1848634538867752e-17">
              <geom name="l_foot" type="mesh" mesh="l_foot" class="collision"></geom>
              <inertial pos="     0.1     0.03        0" mass="1.25" fullinertia="  0.0014   0.0039   0.0041        0        0        0"></inertial>
              <site name="edl_l-P3" pos="0.0919 0.036 -0.0008"></site>
              <site name="edl_l-P4" pos="0.1616 0.0055 -0.013"></site>
              <site name="ehl_l-P4" pos="0.097 0.0389 0.0211"></site>
              <site name="ehl_l-P5" pos="0.1293 0.0309 0.0257"></site>
              <site name="ehl_l-P6" pos="0.1734 0.0139 0.028"></site>
              <site name="fdl_l-P3" pos="0.0436 0.0315 0.028"></site>
              <site name="fdl_l-P4" pos="0.0708 0.0176 0.0263"></site>
              <site name="fdl_l-P5" pos="0.1658 -0.0081 -0.0116"></site>
              <site name="fhl_l-P3" pos="0.0374 0.0276 0.0241"></site>
              <site name="fhl_l-P4" pos="0.1038 0.0068 0.0256"></site>
              <site name="fhl_l-P5" pos="0.1726 -0.0053 0.0269"></site>
              <site name="gaslat_l-P2" pos="0.0044 0.031 0.0053"></site>
              <site name="gasmed_l-P2" pos="0.0044 0.031 0.0053"></site>
              <site name="perbrev_l-P4" pos="0.0471 0.027 -0.0233"></site>
              <site name="perbrev_l-P5" pos="0.0677 0.0219 -0.0343"></site>
              <site name="perlong_l-P4" pos="0.0438 0.023 -0.0221"></site>
              <site name="perlong_l-P5" pos="0.0681 0.0106 -0.0284"></site>
              <site name="perlong_l-P6" pos="0.0852 0.0069 -0.0118"></site>
              <site name="perlong_l-P7" pos="0.1203 0.0085 0.0184"></site>
              <site name="soleus_l-P2" pos="0.0044 0.031 0.0053"></site>
              <site name="tibant_l-P4" pos="0.1166 0.0178 0.0305"></site>
              <site name="tibpost_l-P3" pos="0.0417 0.0334 0.0286"></site>
              <site name="tibpost_l-P4" pos="0.0772 0.0159 0.0281"></site>
              <joint name="subtalar_angle_l" type="hinge" pos="0 0 0" axis="-0.78718 -0.604747 -0.120949" limited="true" range="-0.349066 0.349066" ref="0"></joint>
              <body name="toes_l" pos="  0.1788   -0.002 -0.00108" quat="1.0 1.314867274624753e-31 2.6810890689525335e-17 3.939849802505862e-32">
                <geom name="l_bofoot" type="mesh" mesh="l_bofoot" class="collision"></geom>
                <inertial pos="  0.0346    0.006   0.0175" mass="0.2166" fullinertia="  0.0001   0.0002    0.001        0        0        0"></inertial>
                <site name="edl_l-P5" pos="0.0003 0.0047 -0.0153"></site>
                <site name="edl_l-P6" pos="0.0443 -0.0004 -0.025"></site>
                <site name="ehl_l-P7" pos="0.0298 0.0041 0.0245"></site>
                <site name="ehl_l-P8" pos="0.0563 0.0034 0.0186"></site>
                <site name="fdl_l-P6" pos="-0.0019 -0.0078 -0.0147"></site>
                <site name="fdl_l-P7" pos="0.0285 -0.0071 -0.0215"></site>
                <site name="fdl_l-P8" pos="0.0441 -0.006 -0.0242"></site>
                <site name="fhl_l-P6" pos="0.0155 -0.0064 0.0265"></site>
                <site name="fhl_l-P7" pos="0.0562 -0.0102 0.0181"></site>
                <joint name="mtp_angle_l" type="hinge" pos="0 0 0" axis="-0.580954 2.6299e-15 -0.813936" limited="true" range="-0.523599 0.523599" ref="0"></joint>
              </body>
            </body>
          </body>
        </body>
        <body name="patella_l" pos="-0.00809 -0.40796        0" quat="1.0 0.0 0.0 0.0">
          <geom name="l_patella" type="mesh" mesh="l_patella" class="collision"></geom>
          <inertial pos="  0.0018   0.0264        0" mass="0.0862" fullinertia="2.87e-06 1.311e-05 1.311e-05        0        0        0"></inertial>
          <site name="recfem_l-P2" pos="0.01 0.049 -0.0007"></site>
          <site name="recfem_l-P3" pos="0.0121 0.0437 0.001"></site>
          <site name="recfem_l-P4" pos="0.005 0.00247 -3e-005"></site>
          <site name="vasint_l-P3" pos="0.0058 0.048 0.0006"></site>
          <site name="vasint_l-P4" pos="0.005 0.00247 0.00039"></site>
          <site name="vaslat_l-P3" pos="0.0103 0.0423 -0.0141"></site>
          <site name="vaslat_l-P4" pos="0.005 0.00247 -0.00733"></site>
          <site name="vasmed_l-P3" pos="0.0063 0.0445 0.017"></site>
          <site name="vasmed_l-P4" pos="0.005 0.00247 0.0085"></site>
          <joint name="knee_angle_l_beta_translation2" type="slide" pos="0 0 0" axis="       0        1        0" limited="true" range="-0.0408267 -0.0108281" ref="0"></joint>
          <joint name="knee_angle_l_beta_translation1" type="slide" pos="0 0 0" axis="       1        0        0" limited="true" range="-0.0227731 0.0524192" ref="0"></joint>
          <joint name="knee_angle_l_beta_rotation1" type="hinge" pos="0 0 0" axis="       0        0        1" limited="true" range="-1.79241 0.010506" ref="0"></joint>
        </body>
      </body>
</mujoco>